Workbook
Name codmun: #REF!
Name lista_mun: OFFSET(INDIRECT(#REF!),,,#REF!)
Name niveles: #REF!
Name resultados_2019: '[1]5'!$B$1:$G$60
Name resultados_2020: '[1]6'!$B$1:$G$60
Name resultados_2021: '[1]7'!$B$1:$G$60

Sheet Estructura
A1: FACTOR 1 | B1: CONDICIONES HABILITANTES | D1: Periodo | E1: Último | F1: Pilar | G1: Subpilar | H1: Subpilar en el pilar | I1: Variable en el subpilar | J1: Variable en el pilar
A2: PILAR 1: INSTITUCIONES | C2: INVERSA | D2: Corte | E2: Año | F2: =1/13 -> 0.076923077
A3: INS-1 | B3: Desempeño administrativo | G3: =$F$2/4 -> 0.019230769 | H3: =G3/$F$2 -> 0.25 | L3: 2021 | M3: =COUNTIF(E:E,L3) -> 1 | N3: =M3/92 -> 0.010869565
A4: INS-1-1 | B4: Gestión de recursos | C4: No | D4: 2019-2023 | E4: =IFERROR(MID(D4,6,4),"") -> 2023 | I4: =1/COUNTBLANK($H$4:$H$5) -> 0.5 | J4: =I4*$H$3 -> 0.125 | L4: 2022 | M4: =COUNTIF(E:E,L4) -> 7 | N4: =M4/92 -> 0.076086957
A5: INS-1-2 | B5: Índice de Gobierno Digital para el Estado | C5: No | D5: 2022-2024 | E5: =IFERROR(MID(D5,6,4),"") -> 2024 | I5: =1/COUNTBLANK($H$4:$H$5) -> 0.5 | J5: =I5*$H$3 -> 0.125 | L5: 2023 | M5: =COUNTIF(E:E,L5) -> 23 | N5: =M5/92 -> 0.25
A6: INS-2 | B6: Gestión fiscal | E6: =IFERROR(MID(D6,6,4),"") | G6: =$F$2/4 -> 0.019230769 | H6: =G6/$F$2 -> 0.25 | L6: 2024 | M6: =COUNTIF(E:E,L6) -> 60 | N6: =M6/92 -> 0.65217391
A7: INS-2-1 | B7: Autonomía fiscal | C7: No | D7: 2018-2024 | E7: =IFERROR(MID(D7,6,4),"") -> 2024 | I7: =1/COUNTBLANK($H$7:$H$9) -> 0.33333333 | J7: =I7*$H$6 -> 0.083333333 | L7: 2025 | M7: =COUNTIF(E:E,L7) -> 1 | N7: =M7/92 -> 0.010869565
A8: INS-2-2 | B8: Capacidad local de recaudo | C8: No | D8: 2017-2023 | E8: =IFERROR(MID(D8,6,4),"") -> 2023 | I8: =1/COUNTBLANK($H$7:$H$9) -> 0.33333333 | J8: =I8*$H$6 -> 0.083333333
A9: INS-2-3 | B9: Capacidad de ahorro | C9: No | D9: 2017-2023 | E9: =IFERROR(MID(D9,6,4),"") -> 2023 | I9: =1/COUNTBLANK($H$7:$H$9) -> 0.33333333 | J9: =I9*$H$6 -> 0.083333333
A10: INS-3 | B10: Transparencia y contratación pública | E10: =IFERROR(MID(D10,6,4),"") | G10: =$F$2/4 -> 0.019230769 | H10: =G10/$F$2 -> 0.25
A11: INS-3-1 | B11: Índice de Gobierno Digital para la Sociedad | C11: No | D11: 2022-2024 | E11: =IFERROR(MID(D11,6,4),"") -> 2024 | I11: =1/COUNTBLANK($H$11:$H$12) -> 0.5 | J11: =I11*$H$10 -> 0.125
A12: INS-3-2 | B12: Procesos de contratación en SECOP II | C12: No | D12: 2020-2024 | E12: =IFERROR(MID(D12,6,4),"") -> 2024 | I12: =1/COUNTBLANK($H$11:$H$12) -> 0.5 | J12: =I12*$H$10 -> 0.125
A13: INS-4 | B13: Seguridad y justicia | E13: =IFERROR(MID(D13,6,4),"") | G13: =$F$2/4 -> 0.019230769 | H13: =G13/$F$2 -> 0.25
A14: INS-4-1 | B14: Tasa de homicidios | C14: Sí | D14: 2018-2024 | E14: =IFERROR(MID(D14,6,4),"") -> 2024 | I14: =1/COUNTBLANK($H$14:$H$19) -> 0.16666667 | J14: =I14*$H$13 -> 0.041666667
A15: INS-4-2 | B15: Tasa de hurtos | C15: Sí | D15: 2018-2024 | E15: =IFERROR(MID(D15,6,4),"") -> 2024 | I15: =1/COUNTBLANK($H$14:$H$19) -> 0.16666667 | J15: =I15*$H$13 -> 0.041666667
A16: INS-4-3 | B16: Tasa de extorsión | C16: Sí | D16: 2018-2024 | E16: =IFERROR(MID(D16,6,4),"") -> 2024 | I16: =1/COUNTBLANK($H$14:$H$19) -> 0.16666667 | J16: =I16*$H$13 -> 0.041666667
A17: INS-4-4 | B17: Eficiencia de la justicia | C17: No | D17: 2018-2024 | E17: =IFERROR(MID(D17,6,4),"") -> 2024 | I17: =1/COUNTBLANK($H$14:$H$19) -> 0.16666667 | J17: =I17*$H$13 -> 0.041666667
A18: INS-4-5 | B18: Productividad de jueces | C18: No | D18: 2017-2024 | E18: =IFERROR(MID(D18,6,4),"") -> 2024 | I18: =1/COUNTBLANK($H$14:$H$19) -> 0.16666667 | J18: =I18*$H$13 -> 0.041666667
A19: INS-4-6 | B19: Eficiencia de los métodos de resolución de conflictos | C19: No | D19: 2018-2024 | E19: =IFERROR(MID(D19,6,4),"") -> 2024 | I19: =1/COUNTBLANK($H$14:$H$19) -> 0.16666667 | J19: =I19*$H$13 -> 0.041666667
A20: PILAR 2: INFRAESTRUCTURA Y EQUIPAMIENTO | E20: =IFERROR(MID(D20,6,4),"") | F20: =F2 -> 0.076923077
A21: INF-1 | B21: Infraestructura de servicios | E21: =IFERROR(MID(D21,6,4),"") | G21: =$F$20/3 -> 0.025641026 | H21: =G21/$F$20 -> 0.33333333
A22: INF-1-1 | B22: Cobertura de acueducto | C22: No | D22: 2018-2022 | E22: =IFERROR(MID(D22,6,4),"") -> 2022 | I22: =1/COUNTBLANK($H$22:$H$26) -> 0.2 | J22: =I22*$H$21 -> 0.066666667
A23: INF-1-2 | B23: Cobertura efectiva de gas natural | C23: No | D23: 2018-2024 | E23: =IFERROR(MID(D23,6,4),"") -> 2024 | I23: =1/COUNTBLANK($H$22:$H$26) -> 0.2 | J23: =I23*$H$21 -> 0.066666667
A24: INF-1-3 | B24: Cobertura de la energía eléctrica | C24: No | D24: 2018-2023 | E24: =IFERROR(MID(D24,6,4),"") -> 2023 | I24: =1/COUNTBLANK($H$22:$H$26) -> 0.2 | J24: =I24*$H$21 -> 0.066666667
A25: INF-1-4 | B25: Costo de la energía eléctrica | C25: Sí | D25: 2018-2024 | E25: =IFERROR(MID(D25,6,4),"") -> 2024 | I25: =1/COUNTBLANK($H$22:$H$26) -> 0.2 | J25: =I25*$H$21 -> 0.066666667
A26: INF-1-5 | B26: Cobertura de alcantarillado | C26: No | D26: 2018-2022 | E26: =IFERROR(MID(D26,6,4),"") -> 2022 | I26: =1/COUNTBLANK($H$22:$H$26) -> 0.2 | J26: =I26*$H$21 -> 0.066666667
A27: INF-2 | B27: Conectividad | E27: =IFERROR(MID(D27,6,4),"") | G27: =G21 -> 0.025641026 | H27: =G27/$F$20 -> 0.33333333
A28: INF-2-1 | B28: Costo de transporte terrestre a mercado interno | C28: Sí | D28: 2018-2024 | E28: =IFERROR(MID(D28,6,4),"") -> 2024 | I28: =1/COUNTBLANK($H$28:$H$32) -> 0.2 | J28: =I28*$H$27 -> 0.066666667
A29: INF-2-2 | B29: Costo de transporte terrestre a aduanas | C29: Sí | D29: 2018-2024 | E29: =IFERROR(MID(D29,6,4),"") -> 2024 | I29: =1/COUNTBLANK($H$28:$H$32) -> 0.2 | J29: =I29*$H$27 -> 0.066666667
A30: INF-2-3 | B30: Pasajeros movilizados vía aérea | C30: No | D30: 2018-2024 | E30: =IFERROR(MID(D30,6,4),"") -> 2024 | I30: =1/COUNTBLANK($H$28:$H$32) -> 0.2 | J30: =I30*$H$27 -> 0.066666667
A31: INF-2-4 | B31: Índice de conectividad aérea | C31: No | D31: 2018-2024 | E31: =IFERROR(MID(D31,6,4),"") -> 2024 | I31: =1/COUNTBLANK($H$28:$H$32) -> 0.2 | J31: =I31*$H$27 -> 0.066666667
A32: INF-2-5 | B32: Pasajeros movilizados por transporte público | C32: No | D32: 2019-2025 | E32: =IFERROR(MID(D32,6,4),"") -> 2025 | I32: =1/COUNTBLANK($H$28:$H$32) -> 0.2 | J32: =I32*$H$27 -> 0.066666667
A33: INF-3 | B33: Oferta Cultural | E33: =IFERROR(MID(D33,6,4),"") | G33: =G21 -> 0.025641026 | H33: =G33/$F$20 -> 0.33333333
A34: INF-3-1 | B34: Ejemplares de biblioteca | C34: No | D34: 2018-2023 | E34: =IFERROR(MID(D34,6,4),"") -> 2023 | I34: =1/COUNTBLANK($H$34:$H$36) -> 0.33333333 | J34: =I34*$H$33 -> 0.11111111
A35: INF-3-2 | B35: Museos | C35: No | D35: 2019-2024 | E35: =IFERROR(MID(D35,6,4),"") -> 2024 | I35: =1/COUNTBLANK($H$34:$H$36) -> 0.33333333 | J35: =I35*$H$33 -> 0.11111111
A36: INF-3-3 | B36: Bienes de interés cultural | C36: No | D36: 2019-2024 | E36: =IFERROR(MID(D36,6,4),"") -> 2024 | I36: =1/COUNTBLANK($H$34:$H$36) -> 0.33333333 | J36: =I36*$H$33 -> 0.11111111
A37: PILAR 3: Adopción TIC | E37: =IFERROR(MID(D37,6,4),"") | F37: =F2 -> 0.076923077
A38: TIC-1 | B38: Infraestructura TIC | E38: =IFERROR(MID(D38,6,4),"") | G38: =F37/2 -> 0.038461538 | H38: =G38/$F$37 -> 0.5
A39: TIC-1-1 | B39: Penetración de internet banda ancha fijo | C39: No | D39: 2018-2023 | E39: =IFERROR(MID(D39,6,4),"") -> 2023 | I39: =1/COUNTBLANK($H$39:$H$42) -> 0.25 | J39: =I39*$H$38 -> 0.125
A40: TIC-1-2 | B40: Ancho de banda de internet | C40: No | D40: 2018-2023 | E40: =IFERROR(MID(D40,6,4),"") -> 2023 | I40: =1/COUNTBLANK($H$39:$H$42) -> 0.25 | J40: =I40*$H$38 -> 0.125
...

Sheet Valor_original (winzo-imp)
A1: Ciudad o AM | B1: Año edición | C1: INS-1-1 | D1: INS-1-2 | E1: INS-2-1 | F1: INS-2-2 | G1: INS-2-3 | H1: INS-3-1 | I1: INS-3-2 | J1: INS-4-1 | K1: INS-4-2 | L1: INS-4-3 | M1: INS-4-4 | N1: INS-4-5 | O1: INS-4-6 | P1: INF-1-1 | Q1: INF-1-2 | R1: INF-1-3 | S1: INF-1-4 | T1: INF-1-5 | U1: INF-2-1 | V1: INF-2-2 | W1: INF-2-3 | X1: INF-2-4 | Y1: INF-2-5 | Z1: INF-3-1 | AA1: INF-3-2 | AB1: INF-3-3 | AC1: TIC-1-1 | AD1: TIC-1-2 | AE1: TIC-1-3 | AF1: TIC-1-4 | AG1: TIC-2-1 | AH1: TIC-2-2 | AI1: TIC-2-3 | AJ1: AMB-1-1 | AK1: AMB-1-2 | AL1: AMB-2-1 | AM1: AMB-2-2 | AN1: SAL-1-1 | AO1: SAL-1-2 | AP1: SAL-1-3 | AQ1: SAL-2-1 | AR1: SAL-2-2 | AS1: SAL-3-1 | AT1: SAL-3-2 | AU1: SAL-3-3 | AV1: SAL-3-4 | AW1: EDU-1-1 | AX1: EDU-1-2 | AY1: EDU-1-3 | AZ1: EDU-1-4 | BA1: EDU-1-5 | BB1: EDU-2-1 | BC1: EDU-2-2 | BD1: EDU-2-3 | BE1: EDU-2-4 | BF1: EDS-1-1 | BG1: EDS-1-2 | BH1: EDS-1-3 | BI1: EDS-2-1 | BJ1: EDS-2-2 | BK1: EDS-2-3 | BL1: EDS-2-4 | BM1: EDS-3-1 | BN1: EDS-3-2 | BO1: NEG-1-1 | BP1: NEG-1-2 | BQ1: NEG-1-3 | BR1: NEG-2-1 | BS1: NEG-2-2 | BT1: NEG-2-3 | BU1: LAB-1-1 | BV1: LAB-1-2 | BW1: LAB-1-3 | BX1: LAB-1-4 | BY1: LAB-1-5 | BZ1: FIN-1-1 | CA1: FIN-1-2 | CB1: FIN-1-3 | CC1: FIN-1-4 | CD1: TAM-1-1 | CE1: TAM-2-1 | CF1: TAM-2-2 | CG1: SOF-1-1 | CH1: SOF-1-2 | CI1: INN-1-1 | CJ1: INN-1-2 | CK1: INN-1-3 | CL1: INN-1-4 | CM1: INN-2-1 | CN1: INN-2-2 | CO1: INN-2-3 | CP1: INN-2-4
A2: Arauca | B2: 2019 | C2: 121.14002 | D2: 21.032857 | E2: 0.18219489 | F2: 0.015013936 | G2: 48.123994 | H2: 37.82 | I2: 0.072591526 | J2: 32.716013 | K2: 848.27949 | L2: 63.095169 | M2: 0.43671706 | N2: 288.78261 | O2: 0.58181818 | P2: 47.322365 | Q2: n/a | R2: 95.114412 | S2: 441.02028 | T2: 47.37097 | U2: 180.34663 | V2: 179.64446 | W2: 114012 | X2: 0.1088 | Y2: N/A | Z2: 2102.7049 | AA2: 0 | AB2: 0 | AC2: 7.99 | AD2: 5.5890582 | AE2: 22.427528 | AF2: 68.294633 | AG2: 1312.722 | AH2: 368.053 | AI2: 0.5 | AJ2: 36953.685 | AK2: 41.551358 | AL2: 0 | AM2: 28.831922 | AN2: 1 | AO2: 0.9282 | AP2: 81.320225 | AQ2: 10.848756 | AR2: 61.99628 | AS2: 51.225522 | AT2: 11.709781 | AU2: 5.5688207 | AV2: 269.90711 | AW2: 0.568 | AX2: 0.9594 | AY2: 0.7578 | AZ2: 0.394 | BA2: 0.0296 | BB2: 255 | BC2: 250.66424 | BD2: 0.54151329 | BE2: 26.641309 | BF2: 20.608 | BG2: 19.554 | BH2: 12.428 | BI2: 138.37842 | BJ2: 45.454545 | BK2: 1.3497879 | BL2: 5.5374593 | BM2: 0 | BN2: 0.40883978 | BO2: 0.083916084 | BP2: 0.1386173 | BQ2: 0.064505 | BR2: 6.4263598 | BS2: 6.7418356 | BT2: 0.03812825 | BU2: 61.895839 | BV2: 24.88527 | BW2: 40.146241 | BX2: 10.697331 | BY2: 53.325791 | BZ2: 45.210462 | CA2: 72.968994 | CB2: 0.0039138006 | CC2: 0.16464855 | CD2: 28.240705 | CE2: 26.908411 | CF2: 26.414047 | CG2: 0.305 | CH2: 0.99756022 | CI2: 0 | CJ2: 11.68429 | CK2: 0 | CL2: 0 | CM2: 0 | CN2: 0 | CO2: 0 | CP2: 93.474324
A3: Armenia | B3: 2019 | C3: 202.81292 | D3: 53.9325 | E3: 0.33521994 | F3: 0.029881744 | G3: 52.739413 | H3: 42.44 | I3: 0.39631976 | J3: 29.80949 | K3: 785.54782 | L3: 12.533536 | M3: 0.61884494 | N3: 494.38983 | O3: 0.20596511 | P3: 100 | Q3: 0.8182131 | R3: 99.079541 | S3: 413.186 | T3: 99.998082 | U3: 272.05812 | V3: 235.82489 | W3: 387616 | X3: 0.2414 | Y3: 18.509876 | Z3: 251.2127 | AA3: 9.9935375 | AB3: 13.324717 | AC3: 24.6 | AD3: 8.7742677 | AE3: 41.797892 | AF3: 74.634168 | AG3: 10558.9 | AH3: 1157.081 | AI3: 1.2105 | AJ3: 62669.815 | AK3: 51.516226 | AL3: 1.4519056 | AM3: 31.269909 | AN3: 0.97801545 | AO3: 0.91192768 | AP3: 94.538723 | AQ3: 9.9710518 | AR3: 64.040986 | AS3: 144.446 | AT3: 19.855382 | AU3: 9.7980382 | AV3: 435.62505 | AW3: 0.7119 | AX3: 0.9458 | AY3: 0.9022 | AZ3: 0.5701 | BA3: 0.0428 | BB3: 269 | BC3: 262.25743 | BD3: 0.6025641 | BE3: 24.217338 | BF3: 64.025 | BG3: 97.361 | BH3: 44.424 | BI3: 148.82155 | BJ3: 6.3015312 | BK3: 46.497811 | BL3: 26.928747 | BM3: 59.871383 | BN3: 0.53039514 | BO3: 0.019480519 | BP3: 0.0544573 | BQ3: 0.0782741 | BR3: 11.957671 | BS3: 7.8825777 | BT3: 0.06231199 | BU3: 60.715577 | BV3: 17.088902 | BW3: 47.471812 | BX3: 10.82113 | BY3: 50.017474 | BZ3: 29.360615 | CA3: 109.7289 | CB3: 0.037271891 | CC3: 0.48542031 | CD3: 28.99568 | CE3: 26.713389 | CF3: 13.733634 | CG3: 0.218 | CH3: 0.90263872 | CI3: 2.3712095 | CJ3: 430.20514 | CK3: 1.61 | CL3: 25 | CM3: 20.324652 | CN3: 13.549768 | CO3: 16.93721 | CP3: 752.01214
A4: Barranquilla AM | B4: 2019 | C4: 182.44751 | D4: 71.188127 | E4: 0.38587138 | F4: 0.03571593 | G4: 65.230595 | H4: 49.067451 | I4: 0.28163933 | J4: 26.238484 | K4: 786.82309 | L4: 7.2915366 | M4: 0.46595014 | N4: 338.11 | O4: 0.45842789 | P4: 94.206461 | Q4: 0.89286444 | R4: 99.638348 | S4: 374.13522 | T4: 86.178068 | U4: 169.21186 | V4: 161.11148 | W4: 2482372 | X4: 0.3158 | Y4: 21.942994 | Z4: 581.5829 | AA4: 5.8475771 | AB4: 10.631958 | AC4: 13.838173 | AD4: 11.521319 | AE4: 44.982809 | AF4: 77.643446 | AG4: 7585.936 | AH4: 907.957 | AI4: 2.2895 | AJ4: 99990.406 | AK4: 55.333194 | AL4: 3.4482759 | AM4: 28.368488 | AN4: 0.98546667 | AO4: 0.9770368 | AP4: 91.146548 | AQ4: 12.86013 | AR4: 74.128984 | AS4: 62.196388 | AT4: 27.477631 | AU4: 11.851626 | AV4: 402.91264 | AW4: 0.63985197 | AX4: 0.91119901 | AY4: 0.79399019 | AZ4: 0.51740022 | BA4: 0.0098874718 | BB4: 255.24775 | BC4: 251.02746 | BD4: 0.46319164 | BE4: 29.547495 | BF4: 55.07 | BG4: 429.009 | BH4: 26.464 | BI4: 146.51808 | BJ4: 13.395079 | BK4: 51.227864 | BL4: 30.858676 | BM4: 42.440221 | BN4: 0.4785753 | BO4: 0.11333333 | BP4: 0.0287095 | BQ4: 0.0736313 | BR4: 21.454794 | BS4: 14.442214 | BT4: 0.060929432 | BU4: 64.167768 | BV4: 8.7404648 | BW4: 39.403991 | BX4: 12.407808 | BY4: 48.765305 | BZ4: 45.960873 | CA4: 79.232532 | CB4: 0.041266947 | CC4: 0.76216195 | CD4: 31.041911 | CE4: 28.808833 | CF4: 30.824488 | CG4: 0.099 | CH4: 0.032605743 | CI4: 5.5238914 | CJ4: 475.60705 | CK4: 1.63 | CL4: 21.6 | CM4: 11.047783 | CN4: 3.866724 | CO4: 3.3143348 | CP4: 1083.7875
A5: Bogotá D.C. | B5: 2019 | C5: 194.38686 | D5: 91.9025 | E5: 0.61918234 | F5: 0.038101415 | G5: 62.916318 | H5: 48.215 | I5: 0.65729288 | J5: 14.542872 | K5: 1667.8975 | L5: 10.25286 | M5: 0.54659668 | N5: 597.55 | O5: 0.36015982 | P5: 98.101949 | Q5: 0.96346458 | R5: 99.894262 | S5: 377.72407 | T5: 98.056066 | U5: 243.34343 | V5: 189.77317 | W5: 12843372 | X5: 0.60508 | Y5: 32.036673 | Z5: 691.65253 | AA5: 8.9557692 | AB5: 20.545588 | AC5: 25.31 | AD5: 12.107394 | AE5: 63.897082 | AF5: 87.173928 | AG5: 10166.292 | AH5: 1601.455 | AI5: 2.7656 | AJ5: 40850.186 | AK5: 39.10817 | AL5: 3.0852995 | AM5: 33.456585 | AN5: 0.92496506 | AO5: 0.88670345 | AP5: 88.39084 | AQ5: 8.9094019 | AR5: 56.198461 | AS5: 123.00059 | AT5: 43.938901 | AU5: 27.786599 | AV5: 240.33513 | AW5: 0.7065 | AX5: 0.9781 | AY5: 0.8597 | AZ5: 0.5601 | BA5: 0.0165 | BB5: 274.57283 | BC5: 257.90472 | BD5: 0.37160875 | BE5: 24.15716 | BF5: 79.512 | BG5: 571.929 | BH5: 30.591 | BI5: 155.68934 | BJ5: 8.2291743 | BK5: 33.857732 | BL5: 37.870485 | BM5: 39.621085 | BN5: 0.67928233 | BO5: 0.35774947 | BP5: 0.0052617 | BQ5: 0.0066994 | BR5: 32.586556 | BS5: 25.635927 | BT5: 0.071978866 | BU5: 71.170849 | BV5: 10.60834 | BW5: 56.496643 | BX5: 8.1421844 | BY5: 31.781272 | BZ5: 70.923984 | CA5: 119.03735 | CB5: 0.071459118 | CC5: 0.83183552 | CD5: 32.98897 | CE5: 29.618654 | CF5: 34.266254 | CG5: 0.159 | CH5: 0.020942613 | CI5: 6.043791 | CJ5: 588.46019 | CK5: 2.14 | CL5: 18.8 | CM5: 29.544425 | CN5: 18.347223 | CO5: 38.448224 | CP5: 3325.0294
A6: Bucaramanga AM | B6: 2019 | C6: 202.21521 | D6: 77.063775 | E6: 0.39485024 | F6: 0.025989014 | G6: 60.9875 | H6: 64.75984 | I6: 0.19091127 | J6: 12.54056 | K6: 835.64974 | L6: 10.049058 | M6: 0.51027988 | N6: 482.21081 | O6: 0.45364536 | P6: 69.843314 | Q6: 0.95770278 | R6: 99.520925 | S6: 388.77476 | T6: 64.615611 | U6: 208.33529 | V6: 169.53913 | W6: 1595907 | X6: 0.2756 | Y6: 16.436687 | Z6: 930.22715 | AA6: 7.25342 | AB6: 5.6415489 | AC6: 21.283309 | AD6: 9.425301 | AE6: 50.178464 | AF6: 80.175522 | AG6: 9643.108 | AH6: 1428.933 | AI6: 2.6667 | AJ6: 57402.322 | AK6: 52.176762 | AL6: 3.8112523 | AM6: 28.578598 | AN6: 0.9042601 | AO6: 0.89458273 | AP6: 94.103078 | AQ6: 7.0036541 | AR6: 48.561369 | AS6: 61.977164 | AT6: 22.322031 | AU6: 12.495211 | AV6: 319.57664 | AW6: 0.71440529 | AX6: 0.96476289 | AY6: 0.845617 | AZ6: 0.50737472 | BA6: 0.037678077 | BB6: 287.38174 | BC6: 277.20161 | BD6: 0.71239728 | BE6: 28.227045 | BF6: 56.403 | BG6: 1167.727 | BH6: 30.269 | BI6: 152.18063 | BJ6: 8.2297052 | BK6: 42.674383 | BL6: 31.48729 | BM6: 48.673594 | BN6: 0.55356619 | BO6: 0.073908175 | BP6: 0.0163077 | BQ6: 0.0052737 | BR6: 11.319724 | BS6: 11.891108 | BT6: 0.06153094 | BU6: 63.655162 | BV6: 9.7161008 | BW6: 46.868272 | BX6: 6.8990549 | BY6: 46.862681 | BZ6: 49.039077 | CA6: 92.750939 | CB6: 0.057415759 | CC6: 0.70259627 | CD6: 30.801355 | CE6: 27.709858 | CF6: 8.3574307 | CG6: 0.102 | CH6: 0.40225216 | CI6: 5.0660539 | CJ6: 522.3849 | CK6: 1.36 | CL6: 22.6 | CM6: 14.118511 | CN6: 6.6440051 | CO6: 14.949011 | CP6: 1073.0068
A7: Cali AM | B7: 2019 | C7: 165.31472 | D7: 76.953977 | E7: 0.47258926 | F7: 0.029833391 | G7: 64.417971 | H7: 65.233563 | I7: 0.42674671 | J7: 53.876357 | K7: 991.7875 | L7: 13.490503 | M7: 0.51559143 | N7: 450.46154 | O7: 0.45357238 | P7: 81.743899 | Q7: 0.99742801 | R7: 99.272399 | S7: 366.86036 | T7: 81.363658 | U7: 241.44244 | V7: 196.91324 | W7: 4647659 | X7: 0.373 | Y7: 33.766696 | Z7: 1751.9195 | AA7: 8.9347254 | AB7: 8.5092623 | AC7: 21.094539 | AD7: 10.080154 | AE7: 50.949048 | AF7: 82.960341 | AG7: 6283.943 | AH7: 953.934 | AI7: 1.8246 | AJ7: 77366.662 | AK7: 51.305689 | AL7: 1.9963702 | AM7: 30.038185 | AN7: 0.98227167 | AO7: 0.97858494 | AP7: 93.019595 | AQ7: 9.1225358 | AR7: 30.797659 | AS7: 61.022555 | AT7: 24.634229 | AU7: 12.524895 | AV7: 316.14886 | AW7: 0.53970932 | AX7: 0.78995876 | AY7: 0.75171244 | AZ7: 0.42560379 | BA7: 0.027965355 | BB7: 264.7942 | BC7: 250.68086 | BD7: 0.40927152 | BE7: 30.275644 | BF7: 44.134 | BG7: 211.778 | BH7: 19.054 | BI7: 148.68159 | BJ7: 11.951171 | BK7: 48.375873 | BL7: 31.680815 | BM7: 59.703441 | BN7: 0.59175887 | BO7: 0.15174672 | BP7: 0.0168392 | BQ7: 0.0099212 | BR7: 14.890945 | BS7: 13.504636 | BT7: 0.066850601 | BU7: 65.123023 | BV7: 12.446246 | BW7: 47.208395 | BX7: 11.650437 | BY7: 37.584479 | BZ7: 50.085481 | CA7: 95.458955 | CB7: 0.051213684 | CC7: 0.78080541 | CD7: 31.463177 | CE7: 28.729992 | CF7: 20.712468 | CG7: 0.096 | CH7: 0.022835688 | CI7: 5.610336 | CJ7: 431.69609 | CK7: 1.51 | CL7: 22.98 | CM7: 16.702527 | CN7: 10.278478 | CO7: 13.276368 | CP7: 1997.4509
A8: Cartagena | B8: 2019 | C8: 192.35408 | D8: 75.61 | E8: 0.40941424 | F8: 0.030368381 | G8: 58.927849 | H8: 90.7 | I8: 0.28422725 | J8: 23.431599 | K8: 683.01055 | L8: 10.893638 | M8: 0.54023729 | N8: 421.4252 | O8: 0.258553 | P8: 45.25179 | Q8: 0.93392854 | R8: 95.802788 | S8: 344.49858 | T8: 43.94764 | U8: 174.20999 | V8: 171.04479 | W8: 5259812 | X8: 0.4566 | Y8: 25.61789 | Z8: 677.87204 | AA8: 9.9632853 | AB8: 93.413455 | AC8: 15.48 | AD8: 9.9948442 | AE8: 30.987781 | AF8: 66.898285 | AG8: 4942.26 | AH8: 941.383 | AI8: 1.5897 | AJ8: 118654.95 | AK8: 51.698414 | AL8: 0 | AM8: 27.437401 | AN8: 0.93385827 | AO8: 0.88607929 | AP8: 89.89329 | AQ8: 12.877155 | AR8: 79.482832 | AS8: 38.070441 | AT8: 18.206762 | AU8: 8.76765 | AV8: 379.11916 | AW8: 0.7467 | AX8: 1 | AY8: 0.9123 | AZ8: 0.5445 | BA8: 0.0296 | BB8: 244.87184 | BC8: 229.42514 | BD8: 0.4165937 | BE8: 33.808669 | BF8: 45.886 | BG8: 219.768 | BH8: 37.287 | BI8: 145.79044 | BJ8: 5.9440559 | BK8: 43.274131 | BL8: 25.498551 | BM8: 78.610537 | BN8: 0.3937575 | BO8: 0.20385675 | BP8: 0.3478084 | BQ8: 0.0144095 | BR8: 18.950819 | BS8: 12.607844 | BT8: 0.063009455 | BU8: 66.100392 | BV8: 7.7171083 | BW8: 42.50201 | BX8: 7.3456542 | BY8: 52.041232 | BZ8: 41.620381 | CA8: 82.640895 | CB8: 0.017814944 | CC8: 0.37043469 | CD8: 30.61497 | CE8: 28.838072 | CF8: 45.815469 | CG8: 0.107 | CH8: 0.080207008 | CI8: 3.9052665 | CJ8: 350.44628 | CK8: 0 | CL8: 23.88 | CM8: 2.0554034 | CN8: 1.0277017 | CO8: 8.2216136 | CP8: 612.51021
A9: Cúcuta AM | B9: 2019 | C9: 146.34349 | D9: 68.30965 | E9: 0.23205302 | F9: 0.029309563 | G9: 59.951141 | H9: 50 | I9: 0.13689623 | J9: 26.789807 | K9: 452.09143 | L9: 22.593813 | M9: 0.56000844 | N9: 527.45545 | O9: 0.58007449 | P9: 69.084382 | Q9: 0.73048297 | R9: 98.141035 | S9: 414.31567 | T9: 68.720825 | U9: 167.07386 | V9: 131.95566 | W9: 909214 | X9: 0.2514 | Y9: 13.282548 | Z9: 754.08464 | AA9: 4.0879774 | AB9: 23.50587 | AC9: 13.068041 | AD9: 8.837763 | AE9: 39.469189 | AF9: 74.579021 | AG9: 5727.211 | AH9: 952.619 | AI9: 1.7391 | AJ9: 93883.225 | AK9: 45.332494 | AL9: 1.4519056 | AM9: 27.068235 | AN9: 1 | AO9: 0.9846526 | AP9: 89.058241 | AQ9: 10.066638 | AR9: 56.433409 | AS9: 46.14903 | AT9: 12.053451 | AU9: 6.3351007 | AV9: 235.62119 | AW9: 0.68544458 | AX9: 0.92299251 | AY9: 0.80385345 | AZ9: 0.44518881 | BA9: 0.036967435 | BB9: 266.42892 | BC9: 262.30305 | BD9: 0.64638493 | BE9: 31.652495 | BF9: 48.106 | BG9: 161.673 | BH9: 16.524 | BI9: 142.32564 | BJ9: 6.1524334 | BK9: 16.786082 | BL9: 11.535386 | BM9: 74.948415 | BN9: 0.37247278 | BO9: 0.090342679 | BP9: 0.0125115 | BQ9: 0.0068909 | BR9: 9.0052482 | BS9: 6.1035571 | BT9: 0.048475234 | BU9: 65.61958 | BV9: 15.99521 | BW9: 29.686868 | BX9: 12.585851 | BY9: 64.956299 | BZ9: 29.752443 | CA9: 57.529148 | CB9: 0.0215484 | CC9: 0.38236228 | CD9: 29.860028 | CE9: 26.780554 | CF9: 6.6742125 | CG9: 0.077 | CH9: 0.32438924 | CI9: 0.86071668 | CJ9: 145.24594 | CK9: 1.12 | CL9: 29.79 | CM9: 2.1517917 | CN9: 5.3794792 | CO9: 4.3035834 | CP9: 568.07301
A10: Florencia | B10: 2019 | C10: 156.45196 | D10: 56.255 | E10: 0.18721412 | F10: 0.021905053 | G10: 40.609882 | H10: 61.96 | I10: 0.099370739 | J10: 22.572559 | K10: 906.46644 | L10: 33.264824 | M10: 0.53018679 | N10: 660.51282 | O10: 0.56238004 | P10: 74.686722 | Q10: 0.89457851 | R10: 90.558367 | S10: 434.08757 | T10: 74.686722 | U10: 471.56935 | V10: 421.1808 | W10: 110539 | X10: 0.1192 | Y10: 14.631355 | Z10: 638.86282 | AA10: 5.8560352 | AB10: 5.8560352 | AC10: 11.36 | AD10: 6.1853125 | AE10: 32.606844 | AF10: 67.634542 | AG10: 4545.18 | AH10: 513.068 | AI10: 2.4286 | AJ10: 67122.495 | AK10: 59.578653 | AL10: 7.9854809 | AM10: 28.413185 | AN10: 0.79041057 | AO10: 0.79701407 | AP10: 84.389535 | AQ10: 8.1620314 | AR10: 60.295448 | AS10: 31.429716 | AT10: 8.5106595 | AU10: 3.3097009 | AV10: 370.66518 | AW10: 0.6966 | AX10: 0.981 | AY10: 0.7918 | AZ10: 0.397 | BA10: 0.0498 | BB10: 260 | BC10: 255.74196 | BD10: 0.74040067 | BE10: 28.786311 | BF10: 58.167 | BG10: 216.922 | BH10: 9.083 | BI10: 138.33391 | BJ10: 3.9577836 | BK10: 1.1225444 | BL10: 11.237016 | BM10: 0 | BN10: 0.36120401 | BO10: 0.11904762 | BP10: 0.0399122 | BQ10: 0.0359186 | BR10: 9.4448339 | BS10: 4.562033 | BT10: 0.0390625 | BU10: 61.359637 | BV10: 13.491916 | BW10: 39.729544 | BX10: 6.7605728 | BY10: 47.258958 | BZ10: 53.182153 | CA10: 81.056271 | CB10: 0.011956269 | CC10: 0.46138676 | CD10: 28.221095 | CE10: 19.9213 | CF10: 0.063201732 | CG10: 0.443 | CH10: 0.38555 | CI10: 0 | CJ10: 279.18691 | CK10: 1.4 | CL10: 15.16 | CM10: 5.9401471 | CN10: 0 | CO10: 0 | CP10: 160.38397
A11: Ibagué | B11: 2019 | C11: 166.88325 | D11: 69.86125 | E11: 0.26674732 | F11: 0.019950981 | G11: 56.04685 | H11: 45.35 | I11: 0.56433555 | J11: 15.67117 | K11: 943.10233 | L11: 16.992835 | M11: 0.46223473 | N11: 397.46729 | O11: 0.63340892 | P11: 51.774626 | Q11: 0.96886369 | R11: 98.306345 | S11: 355.16013 | T11: 51.452263 | U11: 134.82491 | V11: 130.09677 | W11: 125335 | X11: 0.2258 | Y11: 21.681067 | Z11: 734.95898 | AA11: 9.3268443 | AB11: 18.653689 | AC11: 20.75 | AD11: 8.5610762 | AE11: 43.924345 | AF11: 78.468172 | AG11: 9662.736 | AH11: 2225.139 | AI11: 1.8571 | AJ11: 59721.499 | AK11: 52.802332 | AL11: 3.8112523 | AM11: 29.113827 | AN11: 0.91719745 | AO11: 0.83642829 | AP11: 92.644217 | AQ11: 7.7463779 | AR11: 14.289797 | AS11: 42.700763 | AT11: 13.374059 | AU11: 6.2021355 | AV11: 312.10173 | AW11: 0.8133 | AX11: 1 | AY11: 0.8778 | AZ11: 0.5059 | BA11: 0.0245 | BB11: 265 | BC11: 258.66043 | BD11: 0.53666557 | BE11: 26.786583 | BF11: 54.001 | BG11: 165.69 | BH11: 32.082 | BI11: 145.96223 | BJ11: 9.2996556 | BK11: 49.386601 | BL11: 16.21919 | BM11: 47.068677 | BN11: 0.43084857 | BO11: 0.28032345 | BP11: 0.0164071 | BQ11: 0.49150035 | BR11: 11.422961 | BS11: 8.7192123 | BT11: 0.038977913 | BU11: 60.936853 | BV11: 15.849759 | BW11: 46.901157 | BX11: 9.418777 | BY11: 39.652223 | BZ11: 50.387127 | CA11: 96.156023 | CB11: 0.023090048 | CC11: 0.5412442 | CD11: 29.692683 | CE11: 26.038854 | CF11: 3.579116 | CG11: 0.206 | CH11: 0.37205178 | CI11: 2.076902 | CJ11: 303.98293 | CK11: 1.64 | CL11: 24.9 | CM11: 5.6642782 | CN11: 3.7761855 | CO11: 15.104742 | CP11: 745.79663
A12: Inírida | B12: 2019 | C12: 108.29779 | D12: 39.751429 | E12: 0.15977471 | F12: 0.015038995 | G12: 46.966529 | H12: 37.79 | I12: 0.0011648224 | J12: 9.5195786 | K12: 339.53164 | L12: 60.290664 | M12: 0 | N12: 291.75 | O12: 0.95238095 | P12: 15.921505 | Q12: n/a | R12: 65.588954 | S12: 487.59824 | T12: 11.468447 | U12: - | V12: - | W12: 50938 | X12: 0.0064 | Y12: N/A | Z12: 2493.495 | AA12: 30.606311 | AB12: 0 | AC12: 2.72 | AD12: 1.1109908 | AE12: 22.482312 | AF12: 49.375557 | AG12: 3212.496 | AH12: 265.252 | AI12: 2.6667 | AJ12: 71352.27 | AK12: 36.348825 | AL12: 3.4482759 | AM12: 31.354344 | AN12: 1 | AO12: 1 | AP12: 37.232525 | AQ12: 13.677812 | AR12: 146.62757 | AS12: 45.101218 | AT12: 7.6900694 | AU12: 2.7019163 | AV12: 142.79368 | AW12: 0.5114 | AX12: 0.7079 | AY12: 0.3764 | AZ12: 0.0919 | BA12: 0.0697 | BB12: 247 | BC12: 247.20513 | BD12: 0.19072165 | BE12: 31.136598 | BF12: 6.098 | BG12: 26.412 | BH12: 12.196 | BI12: 132.61802 | BJ12: 0 | BK12: 4.2031524 | BL12: 4.5454545 | BM12: 0 | BN12: 0.38636364 | BO12: 0 | BP12: 0.2132241 | BQ12: 0.0284747 | BR12: 6.0290664 | BS12: 2.5068224 | BT12: 0.012658228 | BU12: 56.630991 | BV12: 10.561862 | BW12: 39.661555 | BX12: 10.961496 | BY12: 57.186505 | BZ12: 15.711801 | CA12: 87.604512 | CB12: 0 | CC12: 0.020188756 | CD12: 26.264231 | CE12: 19.20545 | CF12: 0.25731801 | CG12: 0.833 | CH12: 0.8330284 | CI12: 0 | CJ12: 0 | CK12: 0 | CL12: 0 | CM12: 0 | CN12: 0 | CO12: 0 | CP12: 0
A13: Leticia | B13: 2019 | C13: 127.32749 | D13: 16.915714 | E13: 0.3715485 | F13: 0.020482322 | G13: 35.822957 | H13: 88.37 | I13: 0 | J13: 14.539714 | K13: 461.11665 | L13: 2.077102 | M13: 0.58212744 | N13: 232.55556 | O13: 0.66666667 | P13: 80.046264 | Q13: n/a | R13: 85.479294 | S13: 473.48746 | T13: 80.046264 | U13: - | V13: - | W13: 247911 | X13: 0.2282 | Y13: N/A | Z13: 793.86839 | AA13: 39.777786 | AB13: 0 | AC13: 1.78 | AD13: 1.7913721 | AE13: 16.252225 | AF13: 44.746427 | AG13: 691.81 | AH13: 66.949 | AI13: 0.5556 | AJ13: 53791.953 | AK13: 13.49192 | AL13: 8.7114338 | AM13: 32.537543 | AN13: 0.78654485 | AO13: 0.826 | AP13: 59.095023 | AQ13: 24.663677 | AR13: 0 | AS13: 57.710637 | AT13: 11.489901 | AU13: 3.9170116 | AV13: 324.02792 | AW13: 0.5555 | AX13: 0.9074 | AY13: 0.8077 | AZ13: 0.4439 | BA13: 0.0592 | BB13: 223 | BC13: 218.93321 | BD13: 0.17716535 | BE13: 26.849081 | BF13: 8.191 | BG13: 40.251 | BH13: 7.05 | BI13: 138.67157 | BJ13: 47.058824 | BK13: 8.8033012 | BL13: 5.8823529 | BM13: 0 | BN13: 0.43298969 | BO13: 0.10638298 | BP13: 0.1589874 | BQ13: 0.018875 | BR13: 7.4775673 | BS13: 5.2342971 | BT13: 0.031746032 | BU13: 60.972763 | BV13: 4.9296759 | BW13: 35.571326 | BX13: 2.0145262 | BY13: 60.46183 | BZ13: 19.442873 | CA13: 67.541007 | CB13: 0.0023012869 | CC13: 0.23587804 | CD13: 26.997833 | CE13: 16.42027 | CF13: 0.30523899 | CG13: 1 | CH13: 1 | CI13: 8.3084081 | CJ13: 373.87836 | CK13: 1.22 | CL13: 63.64 | CM13: 0 | CN13: 0 | CO13: 0 | CP13: 415.42041
A14: Manizales AM | B14: 2019 | C14: 167.83918 | D14: 57.076482 | E14: 0.31097453 | F14: 0.022046608 | G14: 61.653444 | H14: 42.842381 | I14: 0.087453001 | J14: 17.032191 | K14: 474.29642 | L14: 11.221208 | M14: 0.63081647 | N14: 448.82759 | O14: 0.47584541 | P14: 96.610203 | Q14: 0.81584222 | R14: 99.708547 | S14: 440.22713 | T14: 94.567093 | U14: 185.45292 | V14: 172.57167 | W14: 217271 | X14: 0.1268 | Y14: 17.630089 | Z14: 984.84135 | AA14: 9.8658832 | AB14: 27.624473 | AC14: 18.856535 | AD14: 8.3292733 | AE14: 49.998966 | AF14: 77.125178 | AG14: 11628.66 | AH14: 1989.098 | AI14: 3.3846 | AJ14: 87426.13 | AK14: 39.674377 | AL14: 2.3593466 | AM14: 31.642355 | AN14: 0.97418799 | AO14: 0.95699445 | AP14: 94.85957 | AQ14: 9.4928126 | AR14: 54.215234 | AS14: 56.53866 | AT14: 19.12337 | AU14: 10.818879 | AV14: 391.13925 | AW14: 0.65940857 | AX14: 0.78779016 | AY14: 0.75518726 | AZ14: 0.449532 | BA14: 0.026029674 | BB14: 273.19805 | BC14: 262.73574 | BD14: 0.66448363 | BE14: 22.701763 | BF14: 86.31 | BG14: 597.205 | BH14: 27.42 | BI14: 151.10054 | BJ14: 17.542588 | BK14: 66.472142 | BL14: 26.620725 | BM14: 39.042238 | BN14: 0.52691066 | BO14: 0.089068826 | BP14: 0.0616892 | BQ14: 0.0564867 | BR14: 9.5580647 | BS14: 8.792618 | BT14: 0.072242479 | BU14: 62.812797 | BV14: 11.007527 | BW14: 63.727761 | BX14: 5.8938885 | BY14: 30.402534 | BZ14: 26.995728 | CA14: 87.217932 | CB14: 0.042325436 | CC14: 0.54254428 | CD14: 29.590936 | CE14: 27.952462 | CF14: 26.903747 | CG14: 0.127 | CH14: 0.38963531 | CI14: 11.822344 | CJ14: 795.5035 | CK14: 0.97 | CL14: 22.49 | CM14: 18.034084 | CN14: 14.02651 | CO14: 10.018936 | CP14: 1478.7949
A15: Medellín AM | B15: 2019 | C15: 220.95023 | D15: 72.962923 | E15: 0.43794048 | F15: 0.02685362 | G15: 65.461828 | H15: 66.458912 | I15: 0.032156884 | J15: 22.893714 | K15: 1026.1087 | L15: 20.749043 | M15: 0.61549014 | N15: 623.72585 | O15: 0.4875766 | P15: 95.567633 | Q15: 0.92263804 | R15: 99.330783 | S15: 406.44041 | T15: 93.115601 | U15: 363.62828 | V15: 305.0077 | W15: 8785527 | X15: 0.5348 | Y15: 33.21248 | Z15: 2444.4827 | AA15: 6.5504021 | AB15: 13.352743 | AC15: 24.111712 | AD15: 11.062505 | AE15: 50.082136 | AF15: 77.57069 | AG15: 9078.343 | AH15: 1170.358 | AI15: 2.3375 | AJ15: 26807.442 | AK15: 51.485873 | AL15: 1.9963702 | AM15: 31.171347 | AN15: 0.95937267 | AO15: 0.93220021 | AP15: 93.283942 | AQ15: 6.6544918 | AR15: 59.26804 | AS15: 64.147566 | AT15: 23.876629 | AU15: 12.575108 | AV15: 214.13116 | AW15: 0.73357763 | AX15: 0.93130084 | AY15: 0.84449888 | AZ15: 0.48009718 | BA15: 0.037627167 | BB15: 265.22349 | BC15: 256.31555 | BD15: 0.54118801 | BE15: 29.689339 | BF15: 57.847 | BG15: 353.122 | BH15: 28.192 | BI15: 153.66915 | BJ15: 11.5072 | BK15: 39.900369 | BL15: 35.270473 | BM15: 56.669322 | BN15: 0.62269667 | BO15: 0.13841084 | BP15: 0.0076057 | BQ15: 0.0344897 | BR15: 16.312417 | BS15: 14.703656 | BT15: 0.079449599 | BU15: 63.979281 | BV15: 12.672424 | BW15: 60.133688 | BX15: 9.0482298 | BY15: 29.667659 | BZ15: 33.389071 | CA15: 109.48483 | CB15: 0.075281886 | CC15: 0.87029543 | CD15: 32.041474 | CE15: 29.831471 | CF15: 27.78735 | CG15: 0.116 | CH15: 0.0819835 | CI15: 6.4340121 | CJ15: 605.67568 | CK15: 1.28 | CL15: 19.54 | CM15: 28.423347 | CN15: 9.5605802 | CO15: 52.970782 | CP15: 3138.971
A16: Mitú | B16: 2019 | C16: 93.953911 | D16: 16.388333 | E16: 0.14626956 | F16: 0.015483511 | G16: 35.484857 | H16: 73.26 | I16: 0.00068073519 | J16: 10.050251 | K16: 70.351759 | L16: 0 | M16: 0.70775348 | N16: 139 | O16: 0 | P16: 100 | Q16: n/a | R16: 58.050665 | S16: 516.94976 | T16: 100 | U16: - | V16: - | W16: 29768 | X16: 0.0198 | Y16: N/A | Z16: 4111.2228 | AA16: 0 | AB16: 0 | AC16: 0.18 | AD16: 2.4505863 | AE16: 30.926321 | AF16: 43.633623 | AG16: 0 | AH16: 0 | AI16: 0 | AJ16: 65181.287 | AK16: 11.944389 | AL16: 3.4482759 | AM16: 26.25243 | AN16: 0.90833333 | AO16: 0.9094 | AP16: 39.54023 | AQ16: 11.600928 | AR16: 0 | AS16: 27.452999 | AT16: 2.6962767 | AU16: 0.24511606 | AV16: 46.901173 | AW16: 0.2236 | AX16: 0.5591 | AY16: 0.3597 | AZ16: 0.1361 | BA16: 0.0412 | BB16: 215 | BC16: 215.85782 | BD16: 0.17647059 | BE16: 26.894118 | BF16: 1.377 | BG16: 0 | BH16: 5.93 | BI16: 128.53824 | BJ16: 0 | BK16: 0.46948357 | BL16: 0 | BM16: 0 | BN16: 0.375 | BO16: 0.038461538 | BP16: 0.36829102 | BQ16: 0.062254 | BR16: 4.0201005 | BS16: 1.3735343 | BT16: 0 | BU16: 49.090899 | BV16: 7.5628145 | BW16: 52.195869 | BX16: 1.3627559 | BY16: 45.411235 | BZ16: 16.033817 | CA16: 36.885067 | CB16: 0.021418557 | CC16: 0.01515224 | CD16: 26.014343 | CE16: 20.50861 | CF16: 0.40889153 | CG16: 0.877 | CH16: 0.87624985 | CI16: 0 | CJ16: 603.01508 | CK16: 0 | CL16: 0 | CM16: 0 | CN16: 0 | CO16: 0 | CP16: 33.500838
A17: Mocoa | B17: 2019 | C17: 121.2876 | D17: 10.282857 | E17: 0.21072712 | F17: 0.016696154 | G17: 12.07167 | H17: 37.82 | I17: 0.44848036 | J17: 19.504238 | K17: 498.24462 | L17: 19.504238 | M17: 0.56025302 | N17: 311.26087 | O17: 0.53448276 | P17: 49.05938 | Q17: 0.66555296 | R17: 82.604396 | S17: 539.73855 | T17: 45.086705 | U17: 279.30751 | V17: 393.40165 | W17: 34176 | X17: 0 | Y17: N/A | Z17: 1700.4149 | AA17: 0 | AB17: 0 | AC17: 7.09 | AD17: 5.356704 | AE17: 32.153429 | AF17: 60.587651 | AG17: 3203.051 | AH17: 953.289 | AI17: 0.5 | AJ17: 40156.857 | AK17: 6.8907231 | AL17: 4.7186933 | AM17: 36.059756 | AN17: 0.92048193 | AO17: 0.8883 | AP17: 85.227273 | AQ17: 15.963512 | AR17: 0 | AS17: 33.775439 | AT17: 8.3289774 | AU17: 3.3028703 | AV17: 287.24423 | AW17: 0.5065 | AX17: 0.8443 | AY17: 0.8327 | AZ17: 0.3929 | BA17: 0.0473 | BB17: 266 | BC17: 265.68657 | BD17: 0.54941278 | BE17: 21.939559 | BF17: 9.19 | BG17: 38.253 | BH17: 18.571 | BI17: 134.72392 | BJ17: 0 | BK17: 4.5820433 | BL17: 2.2556391 | BM17: 0 | BN17: 0.37139272 | BO17: 0.044444444 | BP17: 0.0701256 | BQ17: 0.0335703 | BR17: 13.121033 | BS17: 6.4186673 | BT17: 0.019337017 | BU17: 59.496235 | BV17: 11.884224 | BW17: 40.957658 | BX17: 2.9530497 | BY17: 41.410057 | BZ17: 19.59138 | CA17: 120.0519 | CB17: 0.017591012 | CC17: 0.32812412 | CD17: 27.211328 | CE17: 25.61826 | CF17: 20.462222 | CG17: 0.232 | CH17: 0.90193047 | CI17: 0 | CJ17: 0 | CK17: 0 | CL17: 0 | CM17: 0 | CN17: 0 | CO17: 0 | CP17: 141.849
A18: Montería | B18: 2019 | C18: 155.16671 | D18: 53.695714 | E18: 0.1756239 | F18: 0.027537717 | G18: 53.802595 | H18: 40.405 | I18: 0.30917052 | J18: 18.943445 | K18: 457.08699 | L18: 14.869586 | M18: 0.54708857 | N18: 439.52542 | O18: 0.49903661 | P18: 85.818141 | Q18: 0.97032855 | R18: 97.942677 | S18: 349.56437 | T18: 45.057205 | U18: 253.24802 | V18: 222.60259 | W18: 925753 | X18: 0.2496 | Y18: 18.014773 | Z18: 326.64202 | AA18: 0 | AB18: 0 | AC18: 11.02 | AD18: 8.0136316 | AE18: 28.751742 | AF18: 61.656988 | AG18: 6138.802 | AH18: 854.741 | AI18: 1.15 | AJ18: 122926.03 | AK18: 36.768132 | AL18: 1.814882 | AM18: 27.104076 | AN18: 0.88900659 | AO18: 0.88631803 | AP18: 88.971808 | AQ18: 20.876572 | AR18: 36.571986 | AS18: 25.532516 | AT18: 11.200241 | AU18: 4.5383668 | AV18: 501.89944 | AW18: 0.6491 | AX18: 0.9512 | AY18: 0.8229 | AZ18: 0.4693 | BA18: 0.0254 | BB18: 263.45934 | BC18: 252.56307 | BD18: 0.40755778 | BE18: 27.135853 | BF18: 65.211 | BG18: 129.026 | BH18: 10.848 | BI18: 142.38257 | BJ18: 8.5295657 | BK18: 66.698354 | BL18: 15.551839 | BM18: 57.534579 | BN18: 0.32232497 | BO18: 0.063636364 | BP18: 0.1092625 | BQ18: 0.1315077 | BR18: 8.555104 | BS18: 6.3389247 | BT18: 0.065874036 | BU18: 69.984093 | BV18: 9.343628 | BW18: 34.011316 | BX18: 7.2911187 | BY18: 48.464089 | BZ18: 23.194459 | CA18: 65.611655 | CB18: 0.020516664 | CC18: 0.64858309 | CD18: 29.162601 | CE18: 26.756417 | CF18: 10.169704 | CG18: 0.232 | CH18: 0.72391246 | CI18: 2.4443154 | CJ18: 315.72408 | CK18: 1.57 | CL18: 26.23 | CM18: 2.0369295 | CN18: 2.0369295 | CO18: 0 | CP18: 258.69005
A19: Neiva | B19: 2019 | C19: 149.95221 | D19: 58.66125 | E19: 0.22765172 | F19: 0.022607482 | G19: 44.732504 | H19: 95.93 | I19: 0.2404943 | J19: 23.503604 | K19: 1089.0003 | L19: 16.508484 | M19: 0.54334043 | N19: 514.14286 | O19: 0.45040984 | P19: 94.752798 | Q19: 0.8967703 | R19: 98.754414 | S19: 371.41246 | T19: 94.752798 | U19: 164.46571 | V19: 150.32974 | W19: 262455 | X19: 0.14 | Y19: 13.583249 | Z19: 748.22604 | AA19: 13.848536 | AB19: 8.3091215 | AC19: 21.05 | AD19: 6.9987286 | AE19: 41.140235 | AF19: 75.008927 | AG19: 8483.581 | AH19: 1162.134 | AI19: 1.1304 | AJ19: 77886.351 | AK19: 53.853321 | AL19: 1.814882 | AM19: 30.834356 | AN19: 0.87143901 | AO19: 0.84421889 | AP19: 95.492123 | AQ19: 9.3739538 | AR19: 33.45041 | AS19: 44.48439 | AT19: 21.901406 | AU19: 9.7874746 | AV19: 429.22058 | AW19: 0.7354 | AX19: 0.9262 | AY19: 0.7924 | AZ19: 0.4643 | BA19: 0.0481 | BB19: 275 | BC19: 265.52419 | BD19: 0.63950276 | BE19: 27.146869 | BF19: 68.709 | BG19: 167.706 | BH19: 17.526 | BI19: 143.4953 | BJ19: 4.3003413 | BK19: 46.842222 | BL19: 13.376988 | BM19: 0 | BN19: 0.38631791 | BO19: 0.10659898 | BP19: 0.0190888 | BQ19: 0.0262272 | BR19: 10.688544 | BS19: 9.9974258 | BT19: 0.037223622 | BU19: 65.949985 | BV19: 11.666187 | BW19: 43.968758 | BX19: 10.064947 | BY19: 52.461997 | BZ19: 43.388146 | CA19: 142.03 | CB19: 0.032899825 | CC19: 0.62507119 | CD19: 29.327077 | CE19: 26.99726 | CF19: 9.9816124 | CG19: 0.235 | CH19: 0.73831909 | CI19: 2.2384385 | CJ19: 235.03604 | CK19: 1.61 | CL19: 16.29 | CM19: 16.788288 | CN19: 0 | CO19: 0 | CP19: 554.01352
A20: Pasto | B20: 2019 | C20: 166.60924 | D20: 42.69375 | E20: 0.2440623 | F20: 0.022255849 | G20: 59.268139 | H20: 45.93 | I20: 0.17287671 | J20: 12.979411 | K20: 1370.7276 | L20: 16.03339 | M20: 0.54149888 | N20: 438.96203 | O20: 0.4862239 | P20: 57.331301 | Q20: 0.23910316 | R20: 97.647431 | S20: 421.17255 | T20: 55.338916 | U20: 227.88356 | V20: 162.00725 | W20: 320855 | X20: 0.129 | Y20: 16.222466 | Z20: 426.84448 | AA20: 25.461619 | AB20: 15.276971 | AC20: 19.64 | AD20: 7.8268089 | AE20: 42.78149 | AF20: 72.128252 | AG20: 8659.218 | AH20: 1326.048 | AI20: 1.3043 | AJ20: 48723.681 | AK20: 30.859835 | AL20: 2.1778584 | AM20: 28.330555 | AN20: 0.9827044 | AO20: 0.93136118 | AP20: 90.659451 | AQ20: 11.012283 | AR20: 63.424947 | AS20: 47.25891 | AT20: 14.037846 | AU20: 5.5439987 | AV20: 612.32281 | AW20: 0.7522 | AX20: 1 | AY20: 0.9836 | AZ20: 0.5491 | BA20: 0.0166 | BB20: 280.31664 | BC20: 273.41802 | BD20: 0.7454844 | BE20: 23.116995 | BF20: 93.752 | BG20: 301.233 | BH20: 12.718 | BI20: 150.57425 | BJ20: 6.870229 | BK20: 33.079035 | BL20: 15.444799 | BM20: 41.480277 | BN20: 0.37359098 | BO20: 0.19285714 | BP20: 0.0157584 | BQ20: 0.5792709 | BR20: 8.0675947 | BS20: 6.1919426 | BT20: 0.060830251 | BU20: 63.872417 | BV20: 9.174385 | BW20: 39.235306 | BX20: 11.803796 | BY20: 44.351318 | BZ20: 44.027336 | CA20: 95.987584 | CB20: 0.027950925 | CC20: 0.53252738 | CD20: 29.28248 | CE20: 25.601987 | CF20: 7.1285296 | CG20: 0.164 | CH20: 0.27679371 | CI20: 1.017993 | CJ20: 463.18683 | CK20: 0.66 | CL20: 19.16 | CM20: 0 | CN20: 0 | CO20: 0 | CP20: 290.12801
A21: Pereira AM | B21: 2019 | C21: 212.94549 | D21: 68.687031 | E21: 0.35678044 | F21: 0.029528508 | G21: 54.712714 | H21: 96.378402 | I21: 0.25860324 | J21: 23.864003 | K21: 538.90534 | L21: 12.914637 | M21: 0.61513804 | N21: 575.96703 | O21: 0.67710985 | P21: 61.13564 | Q21: 0.80084021 | R21: 99.675523 | S21: 390.00571 | T21: 56.387065 | U21: 313.41883 | V21: 256.97066 | W21: 1742190 | X21: 0.2754 | Y21: 26.381994 | Z21: 1081.4043 | AA21: 6.9339184 | AB21: 22.188539 | AC21: 21.649968 | AD21: 9.3829529 | AE21: 51.421193 | AF21: 84.527515 | AG21: 13890.201 | AH21: 1719.192 | AI21: 1.4839 | AJ21: 55847.789 | AK21: 49.307349 | AL21: 4.9001815 | AM21: 31.038908 | AN21: 0.92866525 | AO21: 0.89929386 | AP21: 93.26104 | AQ21: 8.9359362 | AR21: 95.85102 | AS21: 58.511704 | AT21: 24.284477 | AU21: 11.755341 | AV21: 284.26239 | AW21: 0.72912058 | AX21: 1 | AY21: 0.88778685 | AZ21: 0.51215717 | BA21: 0.044599694 | BB21: 266.18296 | BC21: 259.45425 | BD21: 0.49303182 | BE21: 27.213253 | BF21: 77.772 | BG21: 308.497 | BH21: 26.136 | BI21: 146.89639 | BJ21: 7.9752066 | BK21: 49.386757 | BL21: 25.666891 | BM21: 23.998065 | BN21: 0.58693878 | BO21: 0.082932692 | BP21: 0.0262021 | BQ21: 0.0434395 | BR21: 9.1806224 | BS21: 8.9363673 | BT21: 0.068803016 | BU21: 66.903887 | BV21: 8.9596854 | BW21: 48.101108 | BX21: 7.3239056 | BY21: 40.860859 | BZ21: 30.807147 | CA21: 92.216244 | CB21: 0.041327521 | CC21: 0.51491583 | CD21: 30.014016 | CE21: 27.778096 | CF21: 21.374127 | CG21: 0.109 | CH21: 0.26233758 | CI21: 3.2286593 | CJ21: 280.75298 | CK21: 1.32 | CL21: 30.19 | CM21: 19.652709 | CN21: 11.230119 | CO21: 18.248944 | CP21: 1323.7503
A22: Popayán | B22: 2019 | C22: 141.23465 | D22: 28.315 | E22: 0.26275231 | F22: 0.019501512 | G22: 61.323227 | H22: 51.285 | I22: 0.29664651 | J22: 20.750867 | K22: 1493.4336 | L22: 44.016991 | M22: 0.49257691 | N22: 342.17568 | O22: 0.62003454 | P22: 89.829511 | Q22: 0.78968843 | R22: 96.265853 | S22: 380.95534 | T22: 89.829511 | U22: 265.07929 | V22: 253.05493 | W22: 110207 | X22: 0.1192 | Y22: 14.918002 | Z22: 497.26623 | AA22: 18.634061 | AB22: 93.170306 | AC22: 18.09 | AD22: 8.4401735 | AE22: 44.266117 | AF22: 73.673502 | AG22: 17235.375 | AH22: 1837.65 | AI22: 1.75 | AJ22: 47015.21 | AK22: 45.761315 | AL22: 3.8112523 | AM22: 28.117544 | AN22: 0.99199634 | AO22: 0.96424452 | AP22: 91.840316 | AQ22: 10.004764 | AR22: 23.707918 | AS22: 34.544496 | AT22: 11.526213 | AU22: 5.0597888 | AV22: 471.92502 | AW22: 0.6311 | AX22: 0.9699 | AY22: 0.8484 | AZ22: 0.4778 | BA22: 0.0249 | BB22: 272.24484 | BC22: 265.90487 | BD22: 0.67995019 | BE22: 27.283935 | BF22: 105.046 | BG22: 297.083 | BH22: 51.416 | BI22: 147.31347 | BJ22: 8.2398619 | BK22: 40.104986 | BL22: 15.844233 | BM22: 12.520495 | BN22: 0.38963804 | BO22: 0.10055866 | BP22: 0.0279216 | BQ22: 0.0421175 | BR22: 7.5457698 | BS22: 5.6498951 | BT22: 0.042849193 | BU22: 63.383561 | BV22: 10.391371 | BW22: 41.448531 | BX22: 10.54322 | BY22: 51.854207 | BZ22: 47.199287 | CA22: 104.72826 | CB22: 0.033783761 | CC22: 0.43439693 | CD22: 29.061727 | CE22: 26.433097 | CF22: 13.484793 | CG22: 0.109 | CH22: 0.26200494 | CI22: 3.4584778 | CJ22: 468.46654 | CK22: 2.23 | CL22: 20.85 | CM22: 18.864425 | CN22: 0 | CO22: 3.1440708 | CP22: 537.6361
A23: Puerto Carreño | B23: 2019 | C23: 111.293 | D23: 24.574286 | E23: 0.2201201 | F23: 0.025282097 | G23: 48.946475 | H23: 71.79 | I23: 0.0056959772 | J23: 52.541078 | K23: 620.94001 | L23: 57.317539 | M23: 0.62853842 | N23: 253.5 | O23: 0.68571429 | P23: 61.333786 | Q23: n/a | R23: 69.074038 | S23: 405.59447 | T23: 0 | U23: 130.32652 | V23: 135.62295 | W23: 40482 | X23: 0.0034 | Y23: N/A | Z23: 2408.7696 | AA23: 0 | AB23: 0 | AC23: 3.91 | AD23: 1.0861625 | AE23: 23.427662 | AF23: 52.970145 | AG23: 2676.864 | AH23: 286.807 | AI23: 1.25 | AJ23: 77761.886 | AK23: 31.174866 | AL23: 0 | AM23: 28.200001 | AN23: 1 | AO23: 0.9807 | AP23: 65.068493 | AQ23: 26.258206 | AR23: 0 | AS23: 43.039478 | AT23: 4.6378747 | AU23: 2.8754823 | AV23: 200.61139 | AW23: 0.6279 | AX23: 0.9155 | AY23: 0.6097 | AZ23: 0.2633 | BA23: 0.0837 | BB23: 240 | BC23: 239.55758 | BD23: 0.23913043 | BE23: 31.302795 | BF23: 5.635 | BG23: 14.531 | BH23: 33.07 | BI23: 134.4361 | BJ23: 0 | BK23: 0 | BL23: 4.3478261 | BM23: 0 | BN23: 0.46296296 | BO23: 0.014388489 | BP23: 0.2314768 | BQ23: 0.0349768 | BR23: 4.7764616 | BS23: 4.2510508 | BT23: 0.02247191 | BU23: 69.94931 | BV23: 18.072743 | BW23: 36.862535 | BX23: 12.266318 | BY23: 52.424778 | BZ23: 45.276185 | CA23: 78.297615 | CB23: 0.019869875 | CC23: 0.21231397 | CD23: 25.546077 | CE23: 14.741756 | CF23: 0.36134081 | CG23: 1 | CH23: 1 | CI23: 0 | CJ23: 0 | CK23: 0 | CL23: 0 | CM23: 0 | CN23: 0 | CO23: 0 | CP23: 0
A24: Quibdó | B24: 2019 | C24: 116.55622 | D24: 52.468571 | E24: 0.088192172 | F24: 0.0145922 | G24: 54.090672 | H24: 25 | I24: 0.44373866 | J24: 73.508361 | K24: 901.44463 | L24: 64.996866 | M24: 0.48732175 | N24: 242.9697 | O24: 0.58655222 | P24: 43.688484 | Q24: 0.12944822 | R24: 84.901817 | S24: 384.21926 | T24: 16.743591 | U24: 313.78177 | V24: 376.1778 | W24: 329654 | X24: 0.0162 | Y24: 22.556875 | Z24: 293.33705 | AA24: 7.6898233 | AB24: 38.449116 | AC24: 12.1 | AD24: 5.4617991 | AE24: 25.807755 | AF24: 61.449661 | AG24: 5077.838 | AH24: 317.874 | AI24: 1 | AJ24: 75067.205 | AK24: 11.383675 | AL24: 9.2558984 | AM24: 30.886301 | AN24: 0.86061453 | AO24: 0.8481914 | AP24: 73.389884 | AQ24: 23.393855 | AR24: 30.646644 | AS24: 1.2714416 | AT24: 23.933017 | AU24: 2.3746041 | AV24: 326.53188 | AW24: 0.7622 | AX24: 0.967 | AY24: 0.7815 | AZ24: 0.4012 | BA24: 0.0103 | BB24: 220 | BC24: 222.12317 | BD24: 0.59453782 | BE24: 23.953782 | BF24: 98.916 | BG24: 160.669 | BH24: 7.786 | BI24: 125.92891 | BJ24: 3.248731 | BK24: 0.55061095 | BL24: 3.7142857 | BM24: 0 | BN24: 0.25272727 | BO24: 0 | BP24: 0.0569312 | BQ24: 0.0418191 | BR24: 11.68396 | BS24: 7.0800158 | BT24: 0.016393443 | BU24: 62.547303 | BV24: 18.337845 | BW24: 40.016656 | BX24: 4.4187752 | BY24: 51.649352 | BZ24: 46.101949 | CA24: 89.765117 | CB24: 0.007771124 | CC24: 0.27534824 | CD24: 27.916273 | CE24: 25.92316 | CF24: 13.691245 | CG24: 0.564 | CH24: 0.5686953 | CI24: 0.77377222 | CJ24: 123.80355 | CK24: 0 | CL24: 33.33 | CM24: 0 | CN24: 0 | CO24: 0 | CP24: 263.08255
A25: Riohacha | B25: 2019 | C25: 107.56127 | D25: 38.6925 | E25: 0.078742389 | F25: 0.0084998989 | G25: 42.574254 | H25: 53.55 | I25: 0.21068702 | J25: 34.040018 | K25: 658.4616 | L25: 23.402513 | M25: 0.34361027 | N25: 167.82857 | O25: 0.37719298 | P25: 86.087553 | Q25: 0.84676832 | R25: 68.453627 | S25: 402.10983 | T25: 90.001444 | U25: 272.54337 | V25: 211.91106 | W25: 170019 | X25: 0.218 | Y25: N/A | Z25: 1066.6759 | AA25: 0 | AB25: 15.325905 | AC25: 11.59 | AD25: 5.8922053 | AE25: 21.274722 | AF25: 63.880453 | AG25: 4965.623 | AH25: 600.24 | AI25: 1.4444 | AJ25: 99720.75 | AK25: 28.549156 | AL25: 1.9963702 | AM25: 30.770971 | AN25: 0.9205298 | AO25: 0.82188916 | AP25: 74.028238 | AQ25: 17.111786 | AR25: 109.56331 | AS25: 27.596075 | AT25: 10.300263 | AU25: 3.8611792 | AV25: 391.46021 | AW25: 0.8064 | AX25: 1 | AY25: 0.7726 | AZ25: 0.338 | BA25: 0.0316 | BB25: 240 | BC25: 232.30077 | BD25: 0.20585162 | BE25: 26.343783 | BF25: 53.255 | BG25: 38.851 | BH25: 13.164 | BI25: 138.70181 | BJ25: 6.4963504 | BK25: 4.5865417 | BL25: 7.1428571 | BM25: 20.801034 | BN25: 0.32056194 | BO25: 0.047337278 | BP25: 0.0586722 | BQ25: 0.0248476 | BR25: 10.10563 | BS25: 4.6379525 | BT25: 0.029816514 | BU25: 67.152643 | BV25: 14.16324 | BW25: 31.666393 | BX25: 16.517691 | BY25: 62.102157 | BZ25: 21.730506 | CA25: 73.398615 | CB25: 0.016507084 | CC25: 0.25103845 | CD25: 28.329014 | CE25: 27.95877 | CF25: 85.738717 | CG25: 0.159 | CH25: 0.99425058 | CI25: 3.723127 | CJ25: 420.18148 | CK25: 1.67 | CL25: 13.64 | CM25: 0 | CN25: 0 | CO25: 0 | CP25: 101.0563
A26: San Andrés | B26: 2019 | C26: 129.70612 | D26: 71.24 | E26: 0.36534561 | F26: 0.038897161 | G26: 52.03 | H26: 55.95 | I26: 0.44179793 | J26: 45.215315 | K26: 1148.469 | L26: 18.086126 | M26: 0.4717174 | N26: 189.31818 | O26: 0.43181818 | P26: 20.498095 | Q26: n/a | R26: 99.806392 | S26: 423.9339 | T26: 6.7865044 | U26: - | V26: - | W26: 1983714 | X26: 0.264 | Y26: N/A | Z26: 0 | AA26: 0 | AB26: 17.74371 | AC26: 7.27 | AD26: 1.6699863 | AE26: 36.909532 | AF26: 77.338454 | AG26: 6825.282 | AH26: 144.196 | AI26: 0.5 | AJ26: 1822.7651 | AK26: 7.3232895 | AL26: 4.9001815 | AM26: 28.43903 | AN26: 0.95887192 | AO26: 0.9689 | AP26: 92.144638 | AQ26: 16.021362 | AR26: 132.1004 | AS26: 85.672324 | AT26: 44.5256 | AU26: 28.8584 | AV26: 283.95218 | AW26: 0.6952 | AX26: 0.9529 | AY26: 0.8596 | AZ26: 0.5132 | BA26: 0.0219 | BB26: 237 | BC26: 229.58713 | BD26: 0.45945946 | BE26: 23.564865 | BF26: 1.593 | BG26: 18.035 | BH26: 29.405 | BI26: 134.52527 | BJ26: 40.740741 | BK26: 9.3220339 | BL26: 40.123457 | BM26: 83.00885 | BN26: 0.68243243 | BO26: 0 | BP26: 0.2503977 | BQ26: 0.0228667 | BR26: 16.639236 | BS26: 16.132825 | BT26: 0.06838565 | BU26: 72.94158 | BV26: 7.0936768 | BW26: 64.94183 | BX26: 1.2342078 | BY26: 35.211783 | BZ26: 43.244045 | CA26: 112.91391 | CB26: 0.0028047564 | CC26: 0.23938926 | CD26: 27.81758 | CE26: 21.959229 | CF26: 0.67034096 | CG26: 0.334 | CH26: 0.12241218 | CI26: 0 | CJ26: 72.344505 | CK26: 0 | CL26: 0 | CM26: 18.086126 | CN26: 0 | CO26: 0 | CP26: 1501.1485
A27: San José del Guaviare | B27: 2019 | C27: 114.39855 | D27: 43.812857 | E27: 0.16215435 | F27: 0.018614027 | G27: 43.717002 | H27: 90.7 | I27: 0.00047483381 | J27: 32.187825 | K27: 325.66506 | L27: 51.12184 | M27: 0.51636479 | N27: 380 | O27: 0 | P27: 27.156869 | Q27: 0.37061619 | R27: 83.954403 | S27: 538.90693 | T27: 27.156869 | U27: 222.70486 | V27: 238.01354 | W27: 26677 | X27: 0.021 | Y27: N/A | Z27: 2296.696 | AA27: 0 | AB27: 0 | AC27: 4.07 | AD27: 7.0729199 | AE27: 37.631111 | AF27: 69.987768 | AG27: 7627.925 | AH27: 323.378 | AI27: 1.4 | AJ27: 72257.527 | AK27: 20.799281 | AL27: 5.0816697 | AM27: 32.362648 | AN27: 0.96329365 | AO27: 0.9423 | AP27: 67.136659 | AQ27: 19.328586 | AR27: 97.465887 | AS27: 44.945449 | AT27: 8.6991192 | AU27: 2.7788853 | AV27: 200.70056 | AW27: 0.4965 | AX27: 0.9302 | AY27: 0.7797 | AZ27: 0.3641 | BA27: 0.0383 | BB27: 240 | BC27: 237.18345 | BD27: 0.41796875 | BE27: 27.0625 | BF27: 10.827 | BG27: 11.648 | BH27: 29.468 | BI27: 138.47952 | BJ27: 0 | BK27: 0 | BL27: 4 | BM27: 0 | BN27: 0.44954128 | BO27: 0.10638298 | BP27: 0.2060204 | BQ27: 0.0444669 | BR27: 9.8456878 | BS27: 3.9761431 | BT27: 0.014285714 | BU27: 85.349123 | BV27: 11.188238 | BW27: 23.440571 | BX27: 14.344108 | BY27: 45.346824 | BZ27: 50.080923 | CA27: 78.056005 | CB27: 0 | CC27: 0.1541265 | CD27: 26.929023 | CE27: 18.934738 | CF27: 0.10706745 | CG27: 0.69 | CH27: 0.69045677 | CI27: 0 | CJ27: 0 | CK27: 0 | CL27: 0 | CM27: 0 | CN27: 0 | CO27: 0 | CP27: 18.934015
A28: Santa Marta | B28: 2019 | C28: 155.51216 | D28: 78.956667 | E28: 0.2839725 | F28: 0.034354895 | G28: 56.148738 | H28: 43.895 | I28: 0.18933333 | J28: 21.434638 | K28: 756.02173 | L28: 14.623632 | M28: 0.4560801 | N28: 330 | O28: 0.41573816 | P28: 20.685848 | Q28: 0.88160665 | R28: 94.98991 | S28: 314.68221 | T28: 16.953673 | U28: 136.2439 | V28: 138.69181 | W28: 1985735 | X28: 0.2664 | Y28: 39.716099 | Z28: 32.272152 | AA28: 9.5925286 | AB28: 32.614597 | AC28: 14.98 | AD28: 9.5452522 | AE28: 32.415684 | AF28: 65.502062 | AG28: 7050.773 | AH28: 1207.506 | AI28: 2 | AJ28: 167979.51 | AK28: 15.931754 | AL28: 1.6333938 | AM28: 28.382429 | AN28: 0.90235281 | AO28: 0.84314817 | AP28: 89.33506 | AQ28: 10.087862 | AR28: 94.161959 | AS28: 29.513783 | AT28: 12.275051 | AU28: 4.5090501 | AV28: 414.26946 | AW28: 0.6811 | AX28: 0.959 | AY28: 0.8677 | AZ28: 0.5086 | BA28: 0.0377 | BB28: 243.40528 | BC28: 234.35996 | BD28: 0.34204355 | BE28: 31.357789 | BF28: 59.212 | BG28: 194.552 | BH28: 21.593 | BI28: 143.20719 | BJ28: 8.1266491 | BK28: 65.894543 | BL28: 18.660812 | BM28: 43.665437 | BN28: 0.3623431 | BO28: 0.042372881 | BP28: 0.0850895 | BQ28: 0.0412927 | BR28: 16.606837 | BS28: 10.20449 | BT28: 0.056733412 | BU28: 61.420714 | BV28: 8.7916481 | BW28: 35.910617 | BX28: 9.6967028 | BY28: 61.543285 | BZ28: 38.883256 | CA28: 68.961082 | CB28: 0.013764698 | CC28: 0.526567 | CD28: 29.304111 | CE28: 27.582568 | CF28: 22.581276 | CG28: 0.138 | CH28: 0.32337919 | CI28: 4.4071219 | CJ28: 320.51796 | CK28: 1.4 | CL28: 27.23 | CM28: 2.0032372 | CN28: 2.0032372 | CO28: 2.0032372 | CP28: 282.45645
A29: Sincelejo | B29: 2019 | C29: 144.12615 | D29: 43.60375 | E29: 0.17517011 | F29: 0.027402649 | G29: 54.735316 | H29: 43.16 | I29: 0.42192531 | J29: 14.400248 | K29: 774.73333 | L29: 16.560285 | M29: 0.48783668 | N29: 316.33333 | O29: 0.47494033 | P29: 78.058686 | Q29: 0.94503096 | R29: 97.644088 | S29: 380.76289 | T29: 71.326746 | U29: 291.7291 | V29: 248.27287 | W29: 93063 | X29: 0.1116 | Y29: 10.783179 | Z29: 339.88185 | AA29: 3.4887575 | AB29: 0 | AC29: 13.3 | AD29: 7.3443375 | AE29: 28.712519 | AF29: 58.86425 | AG29: 4505.713 | AH29: 927.168 | AI29: 1.125 | AJ29: 98218.52 | AK29: 29.594946 | AL29: 1.814882 | AM29: 25.24472 | AN29: 0.95603968 | AO29: 0.94222752 | AP29: 90.988372 | AQ29: 11.24978 | AR29: 87.443162 | AS29: 33.883582 | AT29: 12.863826 | AU29: 5.2383621 | AV29: 697.33199 | AW29: 0.7975 | AX29: 1 | AY29: 0.8452 | AZ29: 0.5051 | BA29: 0.0267 | BB29: 260 | BC29: 252.52997 | BD29: 0.51019313 | BE29: 28.666309 | BF29: 79.448 | BG29: 91.732 | BH29: 14.46 | BI29: 140.77264 | BJ29: 5.5281343 | BK29: 3.7766259 | BL29: 11.072056 | BM29: 55.3206 | BN29: 0.26790451 | BO29: 0.095652174 | BP29: 0.0234135 | BQ29: 0.065118 | BR29: 10.080173 | BS29: 6.5845133 | BT29: 0.046473483 | BU29: 70.087319 | BV29: 9.994997 | BW29: 29.353862 | BX29: 10.591129 | BY29: 58.120367 | BZ29: 45.649163 | CA29: 67.794253 | CB29: 0.011859836 | CC29: 0.43116737 | CD29: 28.762979 | CE29: 27.64656 | CF29: 33.615867 | CG29: 0.189 | CH29: 0.99255653 | CI29: 1.800031 | CJ29: 324.00557 | CK29: 0.87 | CL29: 16.67 | CM29: 3.6000619 | CN29: 0 | CO29: 0 | CP29: 223.20384
A30: Tunja | B30: 2019 | C30: 176.70667 | D30: 77.376667 | E30: 0.40121735 | F30: 0.024713387 | G30: 51.533474 | H30: 55.43 | I30: 0.28424089 | J30: 4.0568422 | K30: 721.53835 | L30: 16.806917 | M30: 0.50346084 | N30: 255.91892 | O30: 0.54352159 | P30: 92.840528 | Q30: 1 | R30: 98.538834 | S30: 397.9965 | T30: 90.95431 | U30: 273.53083 | V30: 273.53083 | W30: N/A | X30: NA | Y30: 10.3747 | Z30: 503.3382 | AA30: 39.694466 | AB30: 62.377018 | AC30: 23.94 | AD30: 8.0160199 | AE30: 47.805259 | AF30: 76.247644 | AG30: 21081.282 | AH30: 2616.603 | AI30: 3.2308 | AJ30: 35336.873 | AK30: 41.719452 | AL30: 0.1814882 | AM30: 29.995695 | AN30: 0.93272727 | AO30: 0.89433826 | AP30: 91.853035 | AQ30: 9.2670598 | AR30: 0 | AS30: 53.253884 | AT30: 14.038391 | AU30: 5.7336435 | AV30: 460.74136 | AW30: 0.8264 | AX30: 1 | AY30: 0.9462 | AZ30: 0.5286 | BA30: 0.0176 | BB30: 284 | BC30: 275.58228 | BD30: 0.81220096 | BE30: 29.94378 | BF30: 190.859 | BG30: 1301.4873 | BH30: 46.421 | BI30: 153.21666 | BJ30: 9.4611931 | BK30: 60.868014 | BL30: 21.776156 | BM30: 0 | BN30: 0.55945252 | BO30: 0.069565217 | BP30: 0.0148993 | BQ30: 0.0354844 | BR30: 15.76373 | BS30: 10.704268 | BT30: 0.028153763 | BU30: 57.731734 | BV30: 12.68416 | BW30: 56.054846 | BX30: 7.4374328 | BY30: 36.901107 | BZ30: 58.251964 | CA30: 137.91312 | CB30: 0.050307466 | CC30: 0.47190993 | CD30: 28.803472 | CE30: 25.926308 | CF30: 7.3721599 | CG30: 0.278 | CH30: 0.51864539 | CI30: 8.6932332 | CJ30: 1244.7371 | CK30: 1.28 | CL30: 17.22 | CM30: 5.7954888 | CN30: 11.590978 | CO30: 5.7954888 | CP30: 730.23159
A31: Valledupar | B31: 2019 | C31: 144.53203 | D31: 19.667143 | E31: 0.22513223 | F31: 0.028574742 | G31: 63.53361 | H31: 52.565 | I31: 0.38360942 | J31: 17.548334 | K31: 705.60628 | L31: 17.752385 | M31: 0.51081565 | N31: 583.19118 | O31: 0.65326633 | P31: 88.204467 | Q31: 0.90607028 | R31: 95.440166 | S31: 363.93913 | T31: 88.204467 | U31: 204.76159 | V31: 195.07044 | W31: 389395 | X31: 0.2354 | Y31: 11.666302 | Z31: 469.72402 | AA31: 3.8934366 | AB31: 9.7335916 | AC31: 13.81 | AD31: 8.5151088 | AE31: 32.025988 | AF31: 72.015974 | AG31: 6428.461 | AH31: 920.239 | AI31: 1.3125 | AJ31: 116781.84 | AK31: 41.240053 | AL31: 3.6297641 | AM31: 27.576504 | AN31: 0.92075628 | AO31: 0.87414501 | AP31: 88.062244 | AQ31: 11.595745 | AR31: 91.687042 | AS31: 44.895192 | AT31: 16.725333 | AU31: 6.7717608 | AV31: 571.34112 | AW31: 0.6092 | AX31: 0.8625 | AY31: 0.7582 | AZ31: 0.4745 | BA31: 0.0268 | BB31: 256.75113 | BC31: 245.99338 | BD31: 0.35505529 | BE31: 32.855055 | BF31: 53.944 | BG31: 240.836 | BH31: 17.537 | BI31: 141.97336 | BJ31: 6.6225166 | BK31: 1.8222587 | BL31: 12.164074 | BM31: 31.318739 | BN31: 0.35922897 | BO31: 0.036697248 | BP31: 0.0900724 | BQ31: 0.0117954 | BR31: 10.36576 | BS31: 6.2010917 | BT31: 0.048371175 | BU31: 63.547888 | BV31: 15.03892 | BW31: 33.080669 | BX31: 7.9107363 | BY31: 60.173676 | BZ31: 24.353376 | CA31: 63.405243 | CB31: 0.010616879 | CC31: 0.53648057 | CD31: 29.192159 | CE31: 28.79043 | CF31: 72.97288 | CG31: 0.087 | CH31: 0.93268315 | CI31: 1.020252 | CJ31: 102.0252 | CK31: 1.32 | CL31: 41.79 | CM31: 0 | CN31: 0 | CO31: 2.040504 | CP31: 199.96939
A32: Villavicencio | B32: 2019 | C32: 145.99526 | D32: 45.861429 | E32: 0.24882873 | F32: 0.02145242 | G32: 44.040958 | H32: 42.95 | I32: 0.14250914 | J32: 22.587172 | K32: 1126.1588 | L32: 40.65691 | M32: 0.48862663 | N32: 523.65333 | O32: 0.61634506 | P32: 41.236269 | Q32: 0.91566336 | R32: 97.409934 | S32: 371.00246 | T32: 41.136122 | U32: 203.27064 | V32: 212.55383 | W32: 114688 | X32: 0.2742 | Y32: 14.309638 | Z32: 1108.202 | AA32: 1.8558936 | AB32: 0 | AC32: 17.26 | AD32: 9.0018468 | AE32: 42.738748 | AF32: 80.937944 | AG32: 3456.029 | AH32: 768.238 | AI32: 1.1304 | AJ32: 111129.84 | AK32: 31.464776 | AL32: 3.6297641 | AM32: 33.017136 | AN32: 0.8112067 | AO32: 0.77554342 | AP32: 85.281491 | AQ32: 7.9291661 | AR32: 52.687039 | AS32: 44.386865 | AT32: 12.98424 | AU32: 5.3475833 | AV32: 350.47762 | AW32: 0.669 | AX32: 0.9327 | AY32: 0.825 | AZ32: 0.481 | BA32: 0.0382 | BB32: 267 | BC32: 263.92289 | BD32: 0.68347761 | BE32: 30.502823 | BF32: 44.085 | BG32: 128.81 | BH32: 11.107 | BI32: 144.11812 | BJ32: 4.9056604 | BK32: 16.802248 | BL32: 12.330226 | BM32: 20.667168 | BN32: 0.52376514 | BO32: 0.079136691 | BP32: 0.0148065 | BQ32: 0.0778745 | BR32: 13.552303 | BS32: 9.6108418 | BT32: 0.048374461 | BU32: 69.418795 | BV32: 11.934315 | BW32: 41.412114 | BX32: 8.1607865 | BY32: 46.345209 | BZ32: 56.836472 | CA32: 85.211963 | CB32: 0.018638141 | CC32: 0.43308801 | CD32: 29.627254 | CE32: 27.176 | CF32: 9.1731717 | CG32: 0.325 | CH32: 0.99024972 | CI32: 0.75290575 | CJ32: 124.22945 | CK32: 1.39 | CL32: 7 | CM32: 5.6467931 | CN32: 3.7645287 | CO32: 1.8822644 | CP32: 346.33664
A33: Yopal | B33: 2019 | C33: 150.38228 | D33: 44.8925 | E33: 0.35083829 | F33: 0.020819421 | G33: 40.118503 | H33: 70.93 | I33: 0.16153295 | J33: 8.3119104 | K33: 989.71104 | L33: 42.15326 | M33: 0.36123921 | N33: 339.62069 | O33: 0.50431034 | P33: 46.427879 | Q33: 0.9011338 | R33: 97.581804 | S33: 404.16274 | T33: 46.767506 | U33: 156.84955 | V33: 142.11612 | W33: 322762 | X33: 0.1456 | Y33: N/A | Z33: 952.12933 | AA33: 5.7600369 | AB33: 0 | AC33: 13.51 | AD33: 8.8933978 | AE33: 43.496832 | AF33: 75.662099 | AG33: 4859.024 | AH33: 306.886 | AI33: 1 | AJ33: 41216.348 | AK33: 37.824672 | AL33: 1.6333938 | AM33: 34.13717 | AN33: 0.8730209 | AO33: 0.8619 | AP33: 85.791978 | AQ33: 8.5337471 | AR33: 38.299502 | AS33: 48.156498 | AT33: 12.366113 | AU33: 4.9464452 | AV33: 327.72675 | AW33: 0.8297 | AX33: 0.972 | AY33: 0.8716 | AZ33: 0.4852 | BA33: 0.0201 | BB33: 268 | BC33: 262.78808 | BD33: 0.64637198 | BE33: 28.464554 | BF33: 43.513 | BG33: 140.601 | BH33: 15.849 | BI33: 143.91635 | BJ33: 1.6574586 | BK33: 11.935484 | BL33: 9.0666667 | BM33: 0 | BN33: 0.57355372 | BO33: 0.096774194 | BP33: 0.0651126 | BQ33: 0.019376 | BR33: 11.102337 | BS33: 12.242257 | BT33: 0.045101843 | BU33: 71.703718 | BV33: 10.785128 | BW33: 41.158684 | BX33: 6.7966447 | BY33: 42.751285 | BZ33: 59.193011 | CA33: 96.220953 | CB33: 0.00933886 | CC33: 0.29745406 | CD33: 29.110204 | CE33: 27.971055 | CF33: 33.311302 | CG33: 0.428 | CH33: 0.9997913 | CI33: 0 | CJ33: 71.244946 | CK33: 0.08 | CL33: 0 | CM33: 0 | CN33: 0 | CO33: 0 | CP33: 207.79776
A34: Arauca | B34: 2020 | C34: 126.80201 | D34: 21.032857 | E34: 0.1461256 | F34: 0.012 | G34: 55.585659 | H34: 37.82 | I34: 0.072591526 | J34: 35.918367 | K34: 773.87755 | L34: 48.979592 | M34: 0.46868513 | N34: 351.65217 | O34: 0.65502183 | P34: 47.322365 | Q34: n/a | R34: 97.950245 | S34: 447.05829 | T34: 47.37097 | U34: 523.38495 | V34: 360.51223 | W34: 135799 | X34: 0.1088 | Y34: N/A | Z34: 2024.9252 | AA34: 0 | AB34: 0 | AC34: 8.04 | AD34: 7.2683088 | AE34: 22.427528 | AF34: 68.294633 | AG34: 936.308 | AH34: 439.256 | AI34: 0.2857 | AJ34: 36953.685 | AK34: 41.551358 | AL34: 0 | AM34: 28.831922 | AN34: 1 | AO34: 1 | AP34: 75.063776 | AQ34: 10.631229 | AR34: 130.80445 | AS34: 51.587061 | AT34: 11.06712 | AU34: 4.2483462 | AV34: 170.88435 | AW34: 0.5415 | AX34: 0.958 | AY34: 0.7495 | AZ34: 0.3984 | BA34: 0.0343 | BB34: 255 | BC34: 250.66424 | BD34: 0.54151329 | BE34: 26.641309 | BF34: 17.654 | BG34: 40.895 | BH34: 8.796 | BI34: 133.02991 | BJ34: 54.545455 | BK34: 1.1866728 | BL34: 5.4631829 | BM34: 0 | BN34: 0.40883978 | BO34: 0.083916084 | BP34: 0.1386173 | BQ34: 0.064505 | BR34: 11.428571 | BS34: 7.1836735 | BT34: 0.036363636 | BU34: 66.889776 | BV34: 27.200176 | BW34: 38.480528 | BX34: 13.983287 | BY34: 51.732804 | BZ34: 43.633097 | CA34: 73.106292 | CB34: 0.0039138006 | CC34: 0.1827006 | CD34: 28.410281 | CE34: 26.466404 | CF34: 14.35078 | CG34: 0.503 | CH34: 0.98958014 | CI34: 0 | CJ34: 54.421769 | CK34: 0 | CL34: 0 | CM34: 0 | CN34: 0 | CO34: 0 | CP34: 97.959184
